Workbook
Name a: #REF!
Name Ajuste_porcen: #REF!
Name Ajustes: #REF!
Name Año_ocupacion_of: #REF!
Name Año_ocupacion_viv: #REF!
Name CuentaUS: '[1]U$S'!$F$5:$Q$1008
Name CuentaUS2: #REF!
Name CuentaUY: '[1]UY$'!$E$5:$O$993
Name d: #REF!
Name fecha_fin: #REF!
Name fecha_inicio: #REF!
Name Fin_obra_of: #REF!
Name Fin_obra_viv: #REF!
Name m2_alquiler_of: #REF!
Name m2_alquiler_viv: #REF!
Name m2_comerciales_of: #REF!
Name m2_comerciales_viv: #REF!
Name m2_mixto_of: #REF!
Name m2_mixto_viv: #REF!
Name m2_oficinas_of: #REF!
Name m2_oficinas_viv: #REF!
Name m2_totales: #REF!
Name m2_totales_of: #REF!
Name m2_totales_viv: #REF!
Name m2_venta_of: #REF!
Name m2_venta_viv: #REF!
Name m2_vivienda_of: #REF!
Name m2_vivienda_viv: #REF!
Name Ocupacion_an_of: #REF!
Name Ocupacion_an_viv: #REF!
Name US: #REF!

Sheet Efecto TC
B1: Efecto Tipo de Cambio | H1: Resultado Actual | I1: =+H1001+H1005 -> -405618.74
C2: Tipo de Cambio Referencia | F2: 42 | H2: Proyectado | I2: =+L32 -> -185575.32
C3: Tipo de Cambio Proyectado | F3: 42 | H3: Total | I3: =I1+I2 -> -591194.06
C4: Tipo de Cambio Ponderado | F4: =+E1003 -> 39.998222
D5: Fecha | E5: Importe U$S | F5: Importe $ | G5: Tipo de cambio | H5: Efecto Tipo de Cambio | I5: Acumulado | K5: Busqueda | L5: Cambio
A6: =MONTH(D6) -> 11 | B6: =YEAR(D6) -> 2023 | D6: {=IF(ROWS($D6:D$7)>COUNTIF('[1]U$S'!$H$5:$H$1008,$L$5),"",INDEX(CuentaUS,_xlfn.AGGREGATE(15,6,ROW('[1]U$S'!$H$5:$H$1008)-ROW('[1]U$S'!$O$5)+1/--('[1]U$S'!$H$5:$H$1008=$L$5),ROWS($D6:D$7)),1))} -> 45250 | E6: {=IF(ROWS($E6:E$7)>COUNTIF('[1]U$S'!$H$5:$H$1008,$L$5),"",INDEX(CuentaUS,_xlfn.AGGREGATE(15,6,ROW('[1]U$S'!$H$5:$H$1008)-ROW('[1]U$S'!$O$5)+1/--('[1]U$S'!$H$5:$H$1008=$L$5),ROWS($E6:E$7)),6))} -> 2297.67 | F6: =IF(E6="","",IF(E6>0,SUMIFS('[1]UY$'!$L$5:$L$993,'[1]UY$'!$O$5:$O$993,"Cambio",'[1]UY$'!$E$5:$E$993,'Efecto TC'!D6),"")) -> 90000 | G6: =IF(F6="","",F6/E6) -> 39.170116 | H6: =IF(E6="","",F6/$F$2-F6/G6) -> -154.81286 | I6: =+H6 -> -154.81286 | Q6: Mes | R6: =E6/$E$1001 -> 0.00026998289 | S6: =R6*G6 -> 0.010575261 | T6: =MONTH(T8) -> 11 | U6: =MONTH(U8) -> 12 | V6: =MONTH(V8) -> 1 | W6: =MONTH(W8) -> 2 | X6: =MONTH(X8) -> 3 | Y6: =MONTH(Y8) -> 4 | Z6: =MONTH(Z8) -> 5 | AA6: =MONTH(AA8) -> 6 | ... AY6: =MONTH(AY8) -> 6
A7: =MONTH(D7) -> 11 | B7: =YEAR(D7) -> 2023 | D7: {=IF(ROWS($D$7:D7)>COUNTIF('[1]U$S'!$H$5:$H$1008,$L$5),"",INDEX(CuentaUS,_xlfn.AGGREGATE(15,6,ROW('[1]U$S'!$H$5:$H$1008)-ROW('[1]U$S'!$O$5)+1/--('[1]U$S'!$H$5:$H$1008=$L$5),ROWS($D$7:D7)),1))} -> 45239 | E7: {=IF(ROWS($E$7:E7)>COUNTIF('[1]U$S'!$H$5:$H$1008,$L$5),"",INDEX(CuentaUS,_xlfn.AGGREGATE(15,6,ROW('[1]U$S'!$H$5:$H$1008)-ROW('[1]U$S'!$O$5)+1/--('[1]U$S'!$H$5:$H$1008=$L$5),ROWS($E$7:E7)),6))} -> 3780.24 | F7: =IF(E7="","",IF(E7>0,SUMIFS('[1]UY$'!$L$5:$L$993,'[1]UY$'!$O$5:$O$993,"Cambio",'[1]UY$'!$E$5:$E$993,'Efecto TC'!D7),"")) -> 150000 | G7: =IF(F7="","",F7/E7) -> 39.68002 | H7: =IF(E7="","",F7/$F$2-F7/G7) -> -208.81143 | I7: =IF(H7="","",+H7+I6) -> -363.62429 | Q7: Año | R7: =E7/$E$1001 -> 0.00044418916 | S7: =R7*G7 -> 0.017625435 | T7: =YEAR(T8) -> 2023 | U7: =YEAR(U8) -> 2023 | V7: =YEAR(V8) -> 2024 | W7: =YEAR(W8) -> 2024 | X7: =YEAR(X8) -> 2024 | Y7: =YEAR(Y8) -> 2024 | Z7: =YEAR(Z8) -> 2024 | AA7: =YEAR(AA8) -> 2024 | ... AY7: =YEAR(AY8) -> 2026
A8: =MONTH(D8) -> 11 | B8: =YEAR(D8) -> 2023 | D8: {=IF(ROWS($D$7:D8)>COUNTIF('[1]U$S'!$H$5:$H$1008,$L$5),"",INDEX(CuentaUS,_xlfn.AGGREGATE(15,6,ROW('[1]U$S'!$H$5:$H$1008)-ROW('[1]U$S'!$O$5)+1/--('[1]U$S'!$H$5:$H$1008=$L$5),ROWS($D$7:D8)),1))} -> 45250 | E8: {=IF(ROWS($E$7:E8)>COUNTIF('[1]U$S'!$H$5:$H$1008,$L$5),"",INDEX(CuentaUS,_xlfn.AGGREGATE(15,6,ROW('[1]U$S'!$H$5:$H$1008)-ROW('[1]U$S'!$O$5)+1/--('[1]U$S'!$H$5:$H$1008=$L$5),ROWS($E$7:E8)),6))} -> 2297.67 | F8: =IF(E8="","",IF(E8>0,SUMIFS('[1]UY$'!$L$5:$L$993,'[1]UY$'!$O$5:$O$993,"Cambio",'[1]UY$'!$E$5:$E$993,'Efecto TC'!D8),"")) -> 90000 | G8: =IF(F8="","",F8/E8) -> 39.170116 | H8: =IF(E8="","",F8/$F$2-F8/G8) -> -154.81286 | I8: =IF(H8="","",+H8+I7) -> -518.43714 | K8: Pesos Obra total | R8: =E8/$E$1001 -> 0.00026998289 | S8: =R8*G8 -> 0.010575261 | T8: 45231 | U8: 45261 | V8: 45292 | W8: 45323 | X8: 45352 | Y8: 45383 | Z8: 45413 | AA8: 45444 | AB8: 45474 | AC8: 45505 | AD8: 45536 | AE8: 45566 | AF8: 45597 | AG8: 45627 | AH8: 45658 | AI8: 45689 | AJ8: 45717 | AK8: 45748 | AL8: 45778 | AM8: 45809 | AN8: 45839 | AO8: 45870 | AP8: 45901 | AQ8: 45931 | AR8: 45962 | AS8: 45992 | AT8: 46023 | AU8: 46054 | AV8: 46082 | AW8: 46113 | AX8: 46143 | AY8: 46174
A9: =MONTH(D9) -> 11 | B9: =YEAR(D9) -> 2023 | D9: {=IF(ROWS($D$7:D9)>COUNTIF('[1]U$S'!$H$5:$H$1008,$L$5),"",INDEX(CuentaUS,_xlfn.AGGREGATE(15,6,ROW('[1]U$S'!$H$5:$H$1008)-ROW('[1]U$S'!$O$5)+1/--('[1]U$S'!$H$5:$H$1008=$L$5),ROWS($D$7:D9)),1))} -> 45258 | E9: {=IF(ROWS($E$7:E9)>COUNTIF('[1]U$S'!$H$5:$H$1008,$L$5),"",INDEX(CuentaUS,_xlfn.AGGREGATE(15,6,ROW('[1]U$S'!$H$5:$H$1008)-ROW('[1]U$S'!$O$5)+1/--('[1]U$S'!$H$5:$H$1008=$L$5),ROWS($E$7:E9)),6))} -> 5726.07 | F9: =IF(E9="","",IF(E9>0,SUMIFS('[1]UY$'!$L$5:$L$993,'[1]UY$'!$O$5:$O$993,"Cambio",'[1]UY$'!$E$5:$E$993,'Efecto TC'!D9),"")) -> 222000 | G9: =IF(F9="","",F9/E9) -> 38.770046 | H9: =IF(E9="","",F9/$F$2-F9/G9) -> -440.35571 | I9: =IF(H9="","",+H9+I8) -> -958.79286 | R9: =E9/$E$1001 -> 0.00067282983 | S9: =R9*G9 -> 0.026085644 | T9: =SUM(H6:H9) -> -958.79286 | U9: =+H10+H11 -> -782.55048 | X9: =+H12+H13+H14+H15 -> -5656.32 | Y9: =+H16 -> -2680.5362 | AB9: =SUM(H17:H20) -> -1805.8905 | AC9: =SUM(H21:H24) -> -822.31429 | AD9: =SUM(H25:H27) -> -102.65762 | AE9: =SUM(H28:H30) -> -83.272381 | AF9: =SUM(H31:H34) -> 962.73381 | AG9: =SUM(H35:H38) -> 5574.551 | AH9: =SUM(H39:H44) -> 531.3319 | AI9: =SUM(H45:H46) -> 2167.0371 | AJ9: =SUM(H47:H50) -> 437.45048 | AK9: =SUM(H51:H59) -> 6834.6157 | AL9: =SUM(H60:H66) -> -5524.7819 | AM9: =SUM(H67:H71) -> -20403.749 | AN9: =SUM(H72:H76) -> -22349.258 | AO9: =SUM(H77:H81) -> -22142.206 | AP9: =SUM(H82:H83) -> -32453.467 | AQ9: =SUM(H84:H89) -> -32877.938 | AR9: =SUM(H90:H94) -> -50759.281 | AS9: =SUM(H95:H97) -> -51897.919 | AT9: =SUM(H98:H102) -> -59431.809 | AU9: =SUM(H103:H106) -> -31477.903 | AV9: =SUM(H107:H113) -> -17562.854 | AW9: =SUM(H114:H117) -> -6492.9124 | AX9: =SUM(H118:H122) -> -36525.06 | AY9: =SUM(H123:H126) -> -19334.983
A10: =MONTH(D10) -> 12 | B10: =YEAR(D10) -> 2023 | D10: {=IF(ROWS($D$7:D10)>COUNTIF('[1]U$S'!$H$5:$H$1008,$L$5),"",INDEX(CuentaUS,_xlfn.AGGREGATE(15,6,ROW('[1]U$S'!$H$5:$H$1008)-ROW('[1]U$S'!$O$5)+1/--('[1]U$S'!$H$5:$H$1008=$L$5),ROWS($D$7:D10)),1))} -> 45279 | E10: {=IF(ROWS($E$7:E10)>COUNTIF('[1]U$S'!$H$5:$H$1008,$L$5),"",INDEX(CuentaUS,_xlfn.AGGREGATE(15,6,ROW('[1]U$S'!$H$5:$H$1008)-ROW('[1]U$S'!$O$5)+1/--('[1]U$S'!$H$5:$H$1008=$L$5),ROWS($E$7:E10)),6))} -> 1278.77 | F10: =IF(E10="","",IF(E10>0,SUMIFS('[1]UY$'!$L$5:$L$993,'[1]UY$'!$O$5:$O$993,"Cambio",'[1]UY$'!$E$5:$E$993,'Efecto TC'!D10),"")) -> 50000 | G10: =IF(F10="","",F10/E10) -> 39.100073 | H10: =IF(E10="","",F10/$F$2-F10/G10) -> -88.29381 | I10: =IF(H10="","",+H10+I9) -> -1047.0867 | K10: Total PPO Pesos CEAOSA | L10: =+[1]Presupuesto!C9*F2 -> 613337046 | R10: =E10/$E$1001 -> 0.00015025918 | S10: =R10*G10 -> 0.005875145
A11: =MONTH(D11) -> 12 | B11: =YEAR(D11) -> 2023 | D11: {=IF(ROWS($D$7:D11)>COUNTIF('[1]U$S'!$H$5:$H$1008,$L$5),"",INDEX(CuentaUS,_xlfn.AGGREGATE(15,6,ROW('[1]U$S'!$H$5:$H$1008)-ROW('[1]U$S'!$O$5)+1/--('[1]U$S'!$H$5:$H$1008=$L$5),ROWS($D$7:D11)),1))} -> 45288 | E11: {=IF(ROWS($E$7:E11)>COUNTIF('[1]U$S'!$H$5:$H$1008,$L$5),"",INDEX(CuentaUS,_xlfn.AGGREGATE(15,6,ROW('[1]U$S'!$H$5:$H$1008)-ROW('[1]U$S'!$O$5)+1/--('[1]U$S'!$H$5:$H$1008=$L$5),ROWS($E$7:E11)),6))} -> 9027.59 | F11: =IF(E11="","",IF(E11>0,SUMIFS('[1]UY$'!$L$5:$L$993,'[1]UY$'!$O$5:$O$993,"Cambio",'[1]UY$'!$E$5:$E$993,'Efecto TC'!D11),"")) -> 350000 | G11: =IF(F11="","",F11/E11) -> 38.770037 | H11: =IF(E11="","",F11/$F$2-F11/G11) -> -694.25667 | I11: =IF(H11="","",+H11+I10) -> -1741.3433 | K11: Total PPO LLSS | L11: =+[1]Presupuesto!C11*F2 -> 102842560 | R11: =E11/$E$1001 -> 0.001060768 | S11: =R11*G11 -> 0.041126015
A12: =MONTH(D12) -> 3 | B12: =YEAR(D12) -> 2024 | D12: {=IF(ROWS($D$7:D12)>COUNTIF('[1]U$S'!$H$5:$H$1008,$L$5),"",INDEX(CuentaUS,_xlfn.AGGREGATE(15,6,ROW('[1]U$S'!$H$5:$H$1008)-ROW('[1]U$S'!$O$5)+1/--('[1]U$S'!$H$5:$H$1008=$L$5),ROWS($D$7:D12)),1))} -> 45352 | E12: {=IF(ROWS($E$7:E12)>COUNTIF('[1]U$S'!$H$5:$H$1008,$L$5),"",INDEX(CuentaUS,_xlfn.AGGREGATE(15,6,ROW('[1]U$S'!$H$5:$H$1008)-ROW('[1]U$S'!$O$5)+1/--('[1]U$S'!$H$5:$H$1008=$L$5),ROWS($E$7:E12)),6))} -> 3608.24 | F12: =IF(E12="","",IF(E12>0,SUMIFS('[1]UY$'!$L$5:$L$993,'[1]UY$'!$O$5:$O$993,"Cambio",'[1]UY$'!$E$5:$E$993,'Efecto TC'!D12),"")) -> 140000 | G12: =IF(F12="","",F12/E12) -> 38.80008 | H12: =IF(E12="","",F12/$F$2-F12/G12) -> -274.90667 | I12: =IF(H12="","",+H12+I11) -> -2016.25 | K12: Total PPO AJ P. | L12: =+[1]Presupuesto!C53*F2 -> 44780716 | R12: =E12/$E$1001 -> 0.00042397866 | S12: =R12*G12 -> 0.016450406
A13: =MONTH(D13) -> 3 | B13: =YEAR(D13) -> 2024 | D13: {=IF(ROWS($D$7:D13)>COUNTIF('[1]U$S'!$H$5:$H$1008,$L$5),"",INDEX(CuentaUS,_xlfn.AGGREGATE(15,6,ROW('[1]U$S'!$H$5:$H$1008)-ROW('[1]U$S'!$O$5)+1/--('[1]U$S'!$H$5:$H$1008=$L$5),ROWS($D$7:D13)),1))} -> 45370 | E13: {=IF(ROWS($E$7:E13)>COUNTIF('[1]U$S'!$H$5:$H$1008,$L$5),"",INDEX(CuentaUS,_xlfn.AGGREGATE(15,6,ROW('[1]U$S'!$H$5:$H$1008)-ROW('[1]U$S'!$O$5)+1/--('[1]U$S'!$H$5:$H$1008=$L$5),ROWS($E$7:E13)),6))} -> 31054.27 | F13: =IF(E13="","",IF(E13>0,SUMIFS('[1]UY$'!$L$5:$L$993,'[1]UY$'!$O$5:$O$993,"Cambio",'[1]UY$'!$E$5:$E$993,'Efecto TC'!D13),"")) -> 1190000 | G13: =IF(F13="","",F13/E13) -> 38.320012 | H13: =IF(E13="","",F13/$F$2-F13/G13) -> -2720.9367 | I13: =IF(H13="","",+H13+I12) -> -4737.1867 | K13: Total pesos OBRA | L13: =+L10+L11+L12 -> 760960322 | R13: =E13/$E$1001 -> 0.0036489668 | S13: =R13*G13 -> 0.13982845
A14: =MONTH(D14) -> 3 | B14: =YEAR(D14) -> 2024 | D14: {=IF(ROWS($D$7:D14)>COUNTIF('[1]U$S'!$H$5:$H$1008,$L$5),"",INDEX(CuentaUS,_xlfn.AGGREGATE(15,6,ROW('[1]U$S'!$H$5:$H$1008)-ROW('[1]U$S'!$O$5)+1/--('[1]U$S'!$H$5:$H$1008=$L$5),ROWS($D$7:D14)),1))} -> 45371 | E14: {=IF(ROWS($E$7:E14)>COUNTIF('[1]U$S'!$H$5:$H$1008,$L$5),"",INDEX(CuentaUS,_xlfn.AGGREGATE(15,6,ROW('[1]U$S'!$H$5:$H$1008)-ROW('[1]U$S'!$O$5)+1/--('[1]U$S'!$H$5:$H$1008=$L$5),ROWS($E$7:E14)),6))} -> 20927.15 | F14: =IF(E14="","",IF(E14>0,SUMIFS('[1]UY$'!$L$5:$L$993,'[1]UY$'!$O$5:$O$993,"Cambio",'[1]UY$'!$E$5:$E$993,'Efecto TC'!D14),"")) -> 790000 | G14: =IF(F14="","",F14/E14) -> 37.750004 | H14: =IF(E14="","",F14/$F$2-F14/G14) -> -2117.6262 | I14: =IF(H14="","",+H14+I13) -> -6854.8129 | R14: =E14/$E$1001 -> 0.0024590008 | S14: =R14*G14 -> 0.092827291
A15: =MONTH(D15) -> 3 | B15: =YEAR(D15) -> 2024 | D15: {=IF(ROWS($D$7:D15)>COUNTIF('[1]U$S'!$H$5:$H$1008,$L$5),"",INDEX(CuentaUS,_xlfn.AGGREGATE(15,6,ROW('[1]U$S'!$H$5:$H$1008)-ROW('[1]U$S'!$O$5)+1/--('[1]U$S'!$H$5:$H$1008=$L$5),ROWS($D$7:D15)),1))} -> 45373 | E15: {=IF(ROWS($E$7:E15)>COUNTIF('[1]U$S'!$H$5:$H$1008,$L$5),"",INDEX(CuentaUS,_xlfn.AGGREGATE(15,6,ROW('[1]U$S'!$H$5:$H$1008)-ROW('[1]U$S'!$O$5)+1/--('[1]U$S'!$H$5:$H$1008=$L$5),ROWS($E$7:E15)),6))} -> 5066.66 | F15: =IF(E15="","",IF(E15>0,SUMIFS('[1]UY$'!$L$5:$L$993,'[1]UY$'!$O$5:$O$993,"Cambio",'[1]UY$'!$E$5:$E$993,'Efecto TC'!D15),"")) -> 190000 | G15: =IF(F15="","",F15/E15) -> 37.500049 | H15: =IF(E15="","",F15/$F$2-F15/G15) -> -542.85048 | I15: =IF(H15="","",+H15+I14) -> -7397.6633 | K15: Pagos pesos total | R15: =E15/$E$1001 -> 0.00059534724 | S15: =R15*G15 -> 0.022325551
A16: =MONTH(D16) -> 4 | B16: =YEAR(D16) -> 2024 | D16: {=IF(ROWS($D$7:D16)>COUNTIF('[1]U$S'!$H$5:$H$1008,$L$5),"",INDEX(CuentaUS,_xlfn.AGGREGATE(15,6,ROW('[1]U$S'!$H$5:$H$1008)-ROW('[1]U$S'!$O$5)+1/--('[1]U$S'!$H$5:$H$1008=$L$5),ROWS($D$7:D16)),1))} -> 45383 | E16: {=IF(ROWS($E$7:E16)>COUNTIF('[1]U$S'!$H$5:$H$1008,$L$5),"",INDEX(CuentaUS,_xlfn.AGGREGATE(15,6,ROW('[1]U$S'!$H$5:$H$1008)-ROW('[1]U$S'!$O$5)+1/--('[1]U$S'!$H$5:$H$1008=$L$5),ROWS($E$7:E16)),6))} -> 26490.06 | F16: =IF(E16="","",IF(E16>0,SUMIFS('[1]UY$'!$L$5:$L$993,'[1]UY$'!$O$5:$O$993,"Cambio",'[1]UY$'!$E$5:$E$993,'Efecto TC'!D16),"")) -> 1000000 | G16: =IF(F16="","",F16/E16) -> 37.750009 | H16: =IF(E16="","",F16/$F$2-F16/G16) -> -2680.5362 | I16: =IF(H16="","",+H16+I15) -> -10078.2 | R16: =E16/$E$1001 -> 0.0031126589 | S16: =R16*G16 -> 0.1175029
A17: =MONTH(D17) -> 7 | B17: =YEAR(D17) -> 2024 | D17: {=IF(ROWS($D$7:D17)>COUNTIF('[1]U$S'!$H$5:$H$1008,$L$5),"",INDEX(CuentaUS,_xlfn.AGGREGATE(15,6,ROW('[1]U$S'!$H$5:$H$1008)-ROW('[1]U$S'!$O$5)+1/--('[1]U$S'!$H$5:$H$1008=$L$5),ROWS($D$7:D17)),1))} -> 45475 | E17: {=IF(ROWS($E$7:E17)>COUNTIF('[1]U$S'!$H$5:$H$1008,$L$5),"",INDEX(CuentaUS,_xlfn.AGGREGATE(15,6,ROW('[1]U$S'!$H$5:$H$1008)-ROW('[1]U$S'!$O$5)+1/--('[1]U$S'!$H$5:$H$1008=$L$5),ROWS($E$7:E17)),6))} -> 27930.17 | F17: =IF(E17="","",IF(E17>0,SUMIFS('[1]UY$'!$L$5:$L$993,'[1]UY$'!$O$5:$O$993,"Cambio",'[1]UY$'!$E$5:$E$993,'Efecto TC'!D17),"")) -> 1120000 | G17: =IF(F17="","",F17/E17) -> 40.100007 | H17: =IF(E17="","",F17/$F$2-F17/G17) -> -1263.5033 | I17: =IF(H17="","",+H17+I16) -> -11341.703 | K17: Total Pago Pesos CEAOSA | L17: =+'[1]Flujo Gastos (con iva)'!F133*F4 -> 2.3609782e+08 | R17: =E17/$E$1001 -> 0.003281876 | S17: =R17*G17 -> 0.13160325
A18: =MONTH(D18) -> 7 | B18: =YEAR(D18) -> 2024 | D18: {=IF(ROWS($D$7:D18)>COUNTIF('[1]U$S'!$H$5:$H$1008,$L$5),"",INDEX(CuentaUS,_xlfn.AGGREGATE(15,6,ROW('[1]U$S'!$H$5:$H$1008)-ROW('[1]U$S'!$O$5)+1/--('[1]U$S'!$H$5:$H$1008=$L$5),ROWS($D$7:D18)),1))} -> 45482 | E18: {=IF(ROWS($E$7:E18)>COUNTIF('[1]U$S'!$H$5:$H$1008,$L$5),"",INDEX(CuentaUS,_xlfn.AGGREGATE(15,6,ROW('[1]U$S'!$H$5:$H$1008)-ROW('[1]U$S'!$O$5)+1/--('[1]U$S'!$H$5:$H$1008=$L$5),ROWS($E$7:E18)),6))} -> 5527.63 | F18: =IF(E18="","",IF(E18>0,SUMIFS('[1]UY$'!$L$5:$L$993,'[1]UY$'!$O$5:$O$993,"Cambio",'[1]UY$'!$E$5:$E$993,'Efecto TC'!D18),"")) -> 220000 | G18: =IF(F18="","",F18/E18) -> 39.800059 | H18: =IF(E18="","",F18/$F$2-F18/G18) -> -289.53476 | I18: =IF(H18="","",+H18+I17) -> -11631.238 | K18: Total Pago LLSS | L18: =+'[1]Flujo Gastos (con iva)'!F141*F4 -> 46764072 | R18: =E18/$E$1001 -> 0.00064951255 | S18: =R18*G18 -> 0.025850638 | V18: 45231
A19: =MONTH(D19) -> 7 | B19: =YEAR(D19) -> 2024 | D19: {=IF(ROWS($D$7:D19)>COUNTIF('[1]U$S'!$H$5:$H$1008,$L$5),"",INDEX(CuentaUS,_xlfn.AGGREGATE(15,6,ROW('[1]U$S'!$H$5:$H$1008)-ROW('[1]U$S'!$O$5)+1/--('[1]U$S'!$H$5:$H$1008=$L$5),ROWS($D$7:D19)),1))} -> 45496 | E19: {=IF(ROWS($E$7:E19)>COUNTIF('[1]U$S'!$H$5:$H$1008,$L$5),"",INDEX(CuentaUS,_xlfn.AGGREGATE(15,6,ROW('[1]U$S'!$H$5:$H$1008)-ROW('[1]U$S'!$O$5)+1/--('[1]U$S'!$H$5:$H$1008=$L$5),ROWS($E$7:E19)),6))} -> 3624.09 | F19: =IF(E19="","",IF(E19>0,SUMIFS('[1]UY$'!$L$5:$L$993,'[1]UY$'!$O$5:$O$993,"Cambio",'[1]UY$'!$E$5:$E$993,'Efecto TC'!D19),"")) -> 145000 | G19: =IF(F19="","",F19/E19) -> 40.010044 | H19: =IF(E19="","",F19/$F$2-F19/G19) -> -171.70905 | I19: =IF(H19="","",+H19+I18) -> -11802.947 | K19: Total Pago AJ P. | L19: =+'[1]Flujo Gastos (con iva)'!F129*F4 -> 11465255 | R19: =E19/$E$1001 -> 0.00042584108 | S19: =R19*G19 -> 0.01703792 | V19: USD | W19: PESOS | X19: Promedio | Y19: Modelo
A20: =MONTH(D20) -> 7 | B20: =YEAR(D20) -> 2024 | D20: {=IF(ROWS($D$7:D20)>COUNTIF('[1]U$S'!$H$5:$H$1008,$L$5),"",INDEX(CuentaUS,_xlfn.AGGREGATE(15,6,ROW('[1]U$S'!$H$5:$H$1008)-ROW('[1]U$S'!$O$5)+1/--('[1]U$S'!$H$5:$H$1008=$L$5),ROWS($D$7:D20)),1))} -> 45497 | E20: {=IF(ROWS($E$7:E20)>COUNTIF('[1]U$S'!$H$5:$H$1008,$L$5),"",INDEX(CuentaUS,_xlfn.AGGREGATE(15,6,ROW('[1]U$S'!$H$5:$H$1008)-ROW('[1]U$S'!$O$5)+1/--('[1]U$S'!$H$5:$H$1008=$L$5),ROWS($E$7:E20)),6))} -> 1747.81 | F20: =IF(E20="","",IF(E20>0,SUMIFS('[1]UY$'!$L$5:$L$993,'[1]UY$'!$O$5:$O$993,"Cambio",'[1]UY$'!$E$5:$E$993,'Efecto TC'!D20),"")) -> 70000 | G20: =IF(F20="","",F20/E20) -> 40.05012 | H20: =IF(E20="","",F20/$F$2-F20/G20) -> -81.143333 | I20: =IF(H20="","",+H20+I19) -> -11884.09 | K20: Total pesos OBRA | L20: =+L17+L18+L19 -> 2.9432715e+08 | R20: =E20/$E$1001 -> 0.00020537274 | S20: =R20*G20 -> 0.008225203 | V20: =SUM(E6:E9) -> 14101.65 | W20: =SUM(F6:F9) -> 552000 | X20: =AVERAGE(G6:G9) -> 39.197575
A21: =MONTH(D21) -> 8 | B21: =YEAR(D21) -> 2024 | D21: {=IF(ROWS($D$7:D21)>COUNTIF('[1]U$S'!$H$5:$H$1008,$L$5),"",INDEX(CuentaUS,_xlfn.AGGREGATE(15,6,ROW('[1]U$S'!$H$5:$H$1008)-ROW('[1]U$S'!$O$5)+1/--('[1]U$S'!$H$5:$H$1008=$L$5),ROWS($D$7:D21)),1))} -> 45506 | E21: {=IF(ROWS($E$7:E21)>COUNTIF('[1]U$S'!$H$5:$H$1008,$L$5),"",INDEX(CuentaUS,_xlfn.AGGREGATE(15,6,ROW('[1]U$S'!$H$5:$H$1008)-ROW('[1]U$S'!$O$5)+1/--('[1]U$S'!$H$5:$H$1008=$L$5),ROWS($E$7:E21)),6))} -> 6203.47 | F21: =IF(E21="","",IF(E21>0,SUMIFS('[1]UY$'!$L$5:$L$993,'[1]UY$'!$O$5:$O$993,"Cambio",'[1]UY$'!$E$5:$E$993,'Efecto TC'!D21),"")) -> 250000 | G21: =IF(F21="","",F21/E21) -> 40.300026 | H21: =IF(E21="","",F21/$F$2-F21/G21) -> -251.08905 | I21: =IF(H21="","",+H21+I20) -> -12135.179 | R21: =E21/$E$1001 -> 0.00072892571 | S21: =R21*G21 -> 0.029375725
A22: =MONTH(D22) -> 8 | B22: =YEAR(D22) -> 2024 | D22: {=IF(ROWS($D$7:D22)>COUNTIF('[1]U$S'!$H$5:$H$1008,$L$5),"",INDEX(CuentaUS,_xlfn.AGGREGATE(15,6,ROW('[1]U$S'!$H$5:$H$1008)-ROW('[1]U$S'!$O$5)+1/--('[1]U$S'!$H$5:$H$1008=$L$5),ROWS($D$7:D22)),1))} -> 45517 | E22: {=IF(ROWS($E$7:E22)>COUNTIF('[1]U$S'!$H$5:$H$1008,$L$5),"",INDEX(CuentaUS,_xlfn.AGGREGATE(15,6,ROW('[1]U$S'!$H$5:$H$1008)-ROW('[1]U$S'!$O$5)+1/--('[1]U$S'!$H$5:$H$1008=$L$5),ROWS($E$7:E22)),6))} -> 1614.9 | F22: =IF(E22="","",IF(E22>0,SUMIFS('[1]UY$'!$L$5:$L$993,'[1]UY$'!$O$5:$O$993,"Cambio",'[1]UY$'!$E$5:$E$993,'Efecto TC'!D22),"")) -> 65000 | G22: =IF(F22="","",F22/E22) -> 40.25017 | H22: =IF(E22="","",F22/$F$2-F22/G22) -> -67.280952 | I22: =IF(H22="","",+H22+I21) -> -12202.46 | K22: Pendiente pesos total | R22: =E22/$E$1001 -> 0.00018975543 | S22: =R22*G22 -> 0.0076376885
A23: =MONTH(D23) -> 8 | B23: =YEAR(D23) -> 2024 | D23: {=IF(ROWS($D$7:D23)>COUNTIF('[1]U$S'!$H$5:$H$1008,$L$5),"",INDEX(CuentaUS,_xlfn.AGGREGATE(15,6,ROW('[1]U$S'!$H$5:$H$1008)-ROW('[1]U$S'!$O$5)+1/--('[1]U$S'!$H$5:$H$1008=$L$5),ROWS($D$7:D23)),1))} -> 45520 | E23: {=IF(ROWS($E$7:E23)>COUNTIF('[1]U$S'!$H$5:$H$1008,$L$5),"",INDEX(CuentaUS,_xlfn.AGGREGATE(15,6,ROW('[1]U$S'!$H$5:$H$1008)-ROW('[1]U$S'!$O$5)+1/--('[1]U$S'!$H$5:$H$1008=$L$5),ROWS($E$7:E23)),6))} -> 7098.38 | F23: =IF(E23="","",IF(E23>0,SUMIFS('[1]UY$'!$L$5:$L$993,'[1]UY$'!$O$5:$O$993,"Cambio",'[1]UY$'!$E$5:$E$993,'Efecto TC'!D23),"")) -> 285000 | G23: =IF(F23="","",F23/E23) -> 40.150006 | H23: =IF(E23="","",F23/$F$2-F23/G23) -> -312.66571 | I23: =IF(H23="","",+H23+I22) -> -12515.126 | R23: =E23/$E$1001 -> 0.00083408023 | S23: =R23*G23 -> 0.033488326
A24: =MONTH(D24) -> 8 | B24: =YEAR(D24) -> 2024 | D24: {=IF(ROWS($D$7:D24)>COUNTIF('[1]U$S'!$H$5:$H$1008,$L$5),"",INDEX(CuentaUS,_xlfn.AGGREGATE(15,6,ROW('[1]U$S'!$H$5:$H$1008)-ROW('[1]U$S'!$O$5)+1/--('[1]U$S'!$H$5:$H$1008=$L$5),ROWS($D$7:D24)),1))} -> 45530 | E24: {=IF(ROWS($E$7:E24)>COUNTIF('[1]U$S'!$H$5:$H$1008,$L$5),"",INDEX(CuentaUS,_xlfn.AGGREGATE(15,6,ROW('[1]U$S'!$H$5:$H$1008)-ROW('[1]U$S'!$O$5)+1/--('[1]U$S'!$H$5:$H$1008=$L$5),ROWS($E$7:E24)),6))} -> 4119.85 | F24: =IF(E24="","",IF(E24>0,SUMIFS('[1]UY$'!$L$5:$L$993,'[1]UY$'!$O$5:$O$993,"Cambio",'[1]UY$'!$E$5:$E$993,'Efecto TC'!D24),"")) -> 165000 | G24: =IF(F24="","",F24/E24) -> 40.050002 | H24: =IF(E24="","",F24/$F$2-F24/G24) -> -191.27857 | I24: =IF(H24="","",+H24+I23) -> -12706.404 | K24: Pesos pendientes | L24: =+L13-L20 -> 4.6663317e+08 | R24: =E24/$E$1001 -> 0.00048409432 | S24: =R24*G24 -> 0.019387978
A25: =MONTH(D25) -> 9 | B25: =YEAR(D25) -> 2024 | D25: {=IF(ROWS($D$7:D25)>COUNTIF('[1]U$S'!$H$5:$H$1008,$L$5),"",INDEX(CuentaUS,_xlfn.AGGREGATE(15,6,ROW('[1]U$S'!$H$5:$H$1008)-ROW('[1]U$S'!$O$5)+1/--('[1]U$S'!$H$5:$H$1008=$L$5),ROWS($D$7:D25)),1))} -> 45540 | E25: {=IF(ROWS($E$7:E25)>COUNTIF('[1]U$S'!$H$5:$H$1008,$L$5),"",INDEX(CuentaUS,_xlfn.AGGREGATE(15,6,ROW('[1]U$S'!$H$5:$H$1008)-ROW('[1]U$S'!$O$5)+1/--('[1]U$S'!$H$5:$H$1008=$L$5),ROWS($E$7:E25)),6))} -> 1245.01 | F25: =IF(E25="","",IF(E25>0,SUMIFS('[1]UY$'!$L$5:$L$993,'[1]UY$'!$O$5:$O$993,"Cambio",'[1]UY$'!$E$5:$E$993,'Efecto TC'!D25),"")) -> 50000 | G25: =IF(F25="","",F25/E25) -> 40.16032 | H25: =IF(E25="","",F25/$F$2-F25/G25) -> -54.53381 | I25: =IF(H25="","",+H25+I24) -> -12760.938 | R25: =E25/$E$1001 -> 0.00014629229 | S25: =R25*G25 -> 0.005875145
A26: =MONTH(D26) -> 9 | B26: =YEAR(D26) -> 2024 | D26: {=IF(ROWS($D$7:D26)>COUNTIF('[1]U$S'!$H$5:$H$1008,$L$5),"",INDEX(CuentaUS,_xlfn.AGGREGATE(15,6,ROW('[1]U$S'!$H$5:$H$1008)-ROW('[1]U$S'!$O$5)+1/--('[1]U$S'!$H$5:$H$1008=$L$5),ROWS($D$7:D26)),1))} -> 45545 | E26: {=IF(ROWS($E$7:E26)>COUNTIF('[1]U$S'!$H$5:$H$1008,$L$5),"",INDEX(CuentaUS,_xlfn.AGGREGATE(15,6,ROW('[1]U$S'!$H$5:$H$1008)-ROW('[1]U$S'!$O$5)+1/--('[1]U$S'!$H$5:$H$1008=$L$5),ROWS($E$7:E26)),6))} -> 1241.92 | F26: =IF(E26="","",IF(E26>0,SUMIFS('[1]UY$'!$L$5:$L$993,'[1]UY$'!$O$5:$O$993,"Cambio",'[1]UY$'!$E$5:$E$993,'Efecto TC'!D26),"")) -> 50000 | G26: =IF(F26="","",F26/E26) -> 40.260242 | H26: =IF(E26="","",F26/$F$2-F26/G26) -> -51.44381 | I26: =IF(H26="","",+H26+I25) -> -12812.382 | K26: Sensibilidad TC | R26: =E26/$E$1001 -> 0.0001459292 | S26: =R26*G26 -> 0.005875145
A27: =MONTH(D27) -> 9 | B27: =YEAR(D27) -> 2024 | D27: {=IF(ROWS($D$7:D27)>COUNTIF('[1]U$S'!$H$5:$H$1008,$L$5),"",INDEX(CuentaUS,_xlfn.AGGREGATE(15,6,ROW('[1]U$S'!$H$5:$H$1008)-ROW('[1]U$S'!$O$5)+1/--('[1]U$S'!$H$5:$H$1008=$L$5),ROWS($D$7:D27)),1))} -> 45559 | E27: {=IF(ROWS($E$7:E27)>COUNTIF('[1]U$S'!$H$5:$H$1008,$L$5),"",INDEX(CuentaUS,_xlfn.AGGREGATE(15,6,ROW('[1]U$S'!$H$5:$H$1008)-ROW('[1]U$S'!$O$5)+1/--('[1]U$S'!$H$5:$H$1008=$L$5),ROWS($E$7:E27)),6))} -> 4996.68 | F27: =IF(E27="","",IF(E27>0,SUMIFS('[1]UY$'!$L$5:$L$993,'[1]UY$'!$O$5:$O$993,"Cambio",'[1]UY$'!$E$5:$E$993,'Efecto TC'!D27),"")) -> 210000 | G27: =IF(F27="","",F27/E27) -> 42.027907 | H27: =IF(E27="","",F27/$F$2-F27/G27) -> 3.32 | I27: =IF(H27="","",+H27+I26) -> -12809.062 | R27: =E27/$E$1001 -> 0.00058712439 | S27: =R27*G27 -> 0.024675609
A28: =MONTH(D28) -> 10 | B28: =YEAR(D28) -> 2024 | D28: {=IF(ROWS($D$7:D28)>COUNTIF('[1]U$S'!$H$5:$H$1008,$L$5),"",INDEX(CuentaUS,_xlfn.AGGREGATE(15,6,ROW('[1]U$S'!$H$5:$H$1008)-ROW('[1]U$S'!$O$5)+1/--('[1]U$S'!$H$5:$H$1008=$L$5),ROWS($D$7:D28)),1))} -> 45582 | E28: {=IF(ROWS($E$7:E28)>COUNTIF('[1]U$S'!$H$5:$H$1008,$L$5),"",INDEX(CuentaUS,_xlfn.AGGREGATE(15,6,ROW('[1]U$S'!$H$5:$H$1008)-ROW('[1]U$S'!$O$5)+1/--('[1]U$S'!$H$5:$H$1008=$L$5),ROWS($E$7:E28)),6))} -> 1811.59 | F28: =IF(E28="","",IF(E28>0,SUMIFS('[1]UY$'!$L$5:$L$993,'[1]UY$'!$O$5:$O$993,"Cambio",'[1]UY$'!$E$5:$E$993,'Efecto TC'!D28),"")) -> 75000 | G28: =IF(F28="","",F28/E28) -> 41.400096 | H28: =IF(E28="","",F28/$F$2-F28/G28) -> -25.875714 | I28: =IF(H28="","",+H28+I27) -> -12834.938 | K28: 39 | L28: =+N33-N28 -> -854639.51 | N28: =+$L$24/K28 -> 11964953 | R28: =E28/$E$1001 -> 0.00021286708 | S28: =R28*G28 -> 0.0088127175
A29: =MONTH(D29) -> 10 | B29: =YEAR(D29) -> 2024 | D29: {=IF(ROWS($D$7:D29)>COUNTIF('[1]U$S'!$H$5:$H$1008,$L$5),"",INDEX(CuentaUS,_xlfn.AGGREGATE(15,6,ROW('[1]U$S'!$H$5:$H$1008)-ROW('[1]U$S'!$O$5)+1/--('[1]U$S'!$H$5:$H$1008=$L$5),ROWS($D$7:D29)),1))} -> 45595 | E29: {=IF(ROWS($E$7:E29)>COUNTIF('[1]U$S'!$H$5:$H$1008,$L$5),"",INDEX(CuentaUS,_xlfn.AGGREGATE(15,6,ROW('[1]U$S'!$H$5:$H$1008)-ROW('[1]U$S'!$O$5)+1/--('[1]U$S'!$H$5:$H$1008=$L$5),ROWS($E$7:E29)),6))} -> 2184.46 | F29: =IF(E29="","",IF(E29>0,SUMIFS('[1]UY$'!$L$5:$L$993,'[1]UY$'!$O$5:$O$993,"Cambio",'[1]UY$'!$E$5:$E$993,'Efecto TC'!D29),"")) -> 90000 | G29: =IF(F29="","",F29/E29) -> 41.200114 | H29: =IF(E29="","",F29/$F$2-F29/G29) -> -41.602857 | I29: =IF(H29="","",+H29+I28) -> -12876.54 | K29: 39.81 | L29: =+N34-N29 -> -621764.02 | N29: =+$L$24/K29 -> 11721507 | R29: =E29/$E$1001 -> 0.00025668038 | S29: =R29*G29 -> 0.010575261
A30: =MONTH(D30) -> 10 | B30: =YEAR(D30) -> 2024 | D30: {=IF(ROWS($D$7:D30)>COUNTIF('[1]U$S'!$H$5:$H$1008,$L$5),"",INDEX(CuentaUS,_xlfn.AGGREGATE(15,6,ROW('[1]U$S'!$H$5:$H$1008)-ROW('[1]U$S'!$O$5)+1/--('[1]U$S'!$H$5:$H$1008=$L$5),ROWS($D$7:D30)),1))} -> 45596 | E30: {=IF(ROWS($E$7:E30)>COUNTIF('[1]U$S'!$H$5:$H$1008,$L$5),"",INDEX(CuentaUS,_xlfn.AGGREGATE(15,6,ROW('[1]U$S'!$H$5:$H$1008)-ROW('[1]U$S'!$O$5)+1/--('[1]U$S'!$H$5:$H$1008=$L$5),ROWS($E$7:E30)),6))} -> 1206.27 | F30: =IF(E30="","",IF(E30>0,SUMIFS('[1]UY$'!$L$5:$L$993,'[1]UY$'!$O$5:$O$993,"Cambio",'[1]UY$'!$E$5:$E$993,'Efecto TC'!D30),"")) -> 50000 | G30: =IF(F30="","",F30/E30) -> 41.45009 | H30: =IF(E30="","",F30/$F$2-F30/G30) -> -15.79381 | I30: =IF(H30="","",+H30+I29) -> -12892.334 | K30: 40 | L30: =+N33-N30 -> -555515.68 | N30: =+$L$24/K30 -> 11665829 | R30: =E30/$E$1001 -> 0.00014174022 | S30: =R30*G30 -> 0.005875145
A31: =MONTH(D31) -> 11 | B31: =YEAR(D31) -> 2024 | D31: {=IF(ROWS($D$7:D31)>COUNTIF('[1]U$S'!$H$5:$H$1008,$L$5),"",INDEX(CuentaUS,_xlfn.AGGREGATE(15,6,ROW('[1]U$S'!$H$5:$H$1008)-ROW('[1]U$S'!$O$5)+1/--('[1]U$S'!$H$5:$H$1008=$L$5),ROWS($D$7:D31)),1))} -> 45602 | E31: {=IF(ROWS($E$7:E31)>COUNTIF('[1]U$S'!$H$5:$H$1008,$L$5),"",INDEX(CuentaUS,_xlfn.AGGREGATE(15,6,ROW('[1]U$S'!$H$5:$H$1008)-ROW('[1]U$S'!$O$5)+1/--('[1]U$S'!$H$5:$H$1008=$L$5),ROWS($E$7:E31)),6))} -> 1201.92 | F31: =IF(E31="","",IF(E31>0,SUMIFS('[1]UY$'!$L$5:$L$993,'[1]UY$'!$O$5:$O$993,"Cambio",'[1]UY$'!$E$5:$E$993,'Efecto TC'!D31),"")) -> 50000 | G31: =IF(F31="","",F31/E31) -> 41.600106 | H31: =IF(E31="","",F31/$F$2-F31/G31) -> -11.44381 | I31: =IF(H31="","",+H31+I30) -> -12903.778 | K31: 41 | L31: =+N33-N31 -> -270983.26 | N31: =+$L$24/K31 -> 11381297 | R31: =E31/$E$1001 -> 0.00014122909 | S31: =R31*G31 -> 0.005875145
A32: =MONTH(D32) -> 11 | B32: =YEAR(D32) -> 2024 | D32: {=IF(ROWS($D$7:D32)>COUNTIF('[1]U$S'!$H$5:$H$1008,$L$5),"",INDEX(CuentaUS,_xlfn.AGGREGATE(15,6,ROW('[1]U$S'!$H$5:$H$1008)-ROW('[1]U$S'!$O$5)+1/--('[1]U$S'!$H$5:$H$1008=$L$5),ROWS($D$7:D32)),1))} -> 45607 | E32: {=IF(ROWS($E$7:E32)>COUNTIF('[1]U$S'!$H$5:$H$1008,$L$5),"",INDEX(CuentaUS,_xlfn.AGGREGATE(15,6,ROW('[1]U$S'!$H$5:$H$1008)-ROW('[1]U$S'!$O$5)+1/--('[1]U$S'!$H$5:$H$1008=$L$5),ROWS($E$7:E32)),6))} -> 1185.95 | F32: =IF(E32="","",IF(E32>0,SUMIFS('[1]UY$'!$L$5:$L$993,'[1]UY$'!$O$5:$O$993,"Cambio",'[1]UY$'!$E$5:$E$993,'Efecto TC'!D32),"")) -> 50000 | G32: =IF(F32="","",F32/E32) -> 42.160293 | H32: =IF(E32="","",F32/$F$2-F32/G32) -> 4.5261905 | I32: =IF(H32="","",+H32+I31) -> -12899.252 | K32: 41.31 | L32: =+N33-N32 -> -185575.32 | N32: =+$L$24/K32 -> 11295889 | R32: =E32/$E$1001 -> 0.00013935256 | S32: =R32*G32 -> 0.005875145
A33: =MONTH(D33) -> 11 | B33: =YEAR(D33) -> 2024 | D33: {=IF(ROWS($D$7:D33)>COUNTIF('[1]U$S'!$H$5:$H$1008,$L$5),"",INDEX(CuentaUS,_xlfn.AGGREGATE(15,6,ROW('[1]U$S'!$H$5:$H$1008)-ROW('[1]U$S'!$O$5)+1/--('[1]U$S'!$H$5:$H$1008=$L$5),ROWS($D$7:D33)),1))} -> 45621 | E33: {=IF(ROWS($E$7:E33)>COUNTIF('[1]U$S'!$H$5:$H$1008,$L$5),"",INDEX(CuentaUS,_xlfn.AGGREGATE(15,6,ROW('[1]U$S'!$H$5:$H$1008)-ROW('[1]U$S'!$O$5)+1/--('[1]U$S'!$H$5:$H$1008=$L$5),ROWS($E$7:E33)),6))} -> 47563.26 | F33: =IF(E33="","",IF(E33>0,SUMIFS('[1]UY$'!$L$5:$L$993,'[1]UY$'!$O$5:$O$993,"Cambio",'[1]UY$'!$E$5:$E$993,'Efecto TC'!D33),"")) -> 2030000 | G33: =IF(F33="","",F33/E33) -> 42.680001 | H33: =IF(E33="","",F33/$F$2-F33/G33) -> 770.07333 | I33: =IF(H33="","",+H33+I32) -> -12129.179 | K33: 42 | L33: 0 | N33: =+$L$24/K33 -> 11110314 | R33: =E33/$E$1001 -> 0.005588821 | S33: =R33*G33 -> 0.23853089
A34: =MONTH(D34) -> 11 | B34: =YEAR(D34) -> 2024 | D34: {=IF(ROWS($D$7:D34)>COUNTIF('[1]U$S'!$H$5:$H$1008,$L$5),"",INDEX(CuentaUS,_xlfn.AGGREGATE(15,6,ROW('[1]U$S'!$H$5:$H$1008)-ROW('[1]U$S'!$O$5)+1/--('[1]U$S'!$H$5:$H$1008=$L$5),ROWS($D$7:D34)),1))} -> 45622 | E34: {=IF(ROWS($E$7:E34)>COUNTIF('[1]U$S'!$H$5:$H$1008,$L$5),"",INDEX(CuentaUS,_xlfn.AGGREGATE(15,6,ROW('[1]U$S'!$H$5:$H$1008)-ROW('[1]U$S'!$O$5)+1/--('[1]U$S'!$H$5:$H$1008=$L$5),ROWS($E$7:E34)),6))} -> 12895.66 | F34: =IF(E34="","",IF(E34>0,SUMIFS('[1]UY$'!$L$5:$L$993,'[1]UY$'!$O$5:$O$993,"Cambio",'[1]UY$'!$E$5:$E$993,'Efecto TC'!D34),"")) -> 550000 | G34: =IF(F34="","",F34/E34) -> 42.650008 | H34: =IF(E34="","",F34/$F$2-F34/G34) -> 199.5781 | I34: =IF(H34="","",+H34+I33) -> -11929.6 | K34: 42.04 | L34: =+N33-N34 -> 10571.183 | N34: =+$L$24/K34 -> 11099742 | R34: =E34/$E$1001 -> 0.0015152774 | S34: =R34*G34 -> 0.064626595
A35: =MONTH(D35) -> 12 | B35: =YEAR(D35) -> 2024 | D35: {=IF(ROWS($D$7:D35)>COUNTIF('[1]U$S'!$H$5:$H$1008,$L$5),"",INDEX(CuentaUS,_xlfn.AGGREGATE(15,6,ROW('[1]U$S'!$H$5:$H$1008)-ROW('[1]U$S'!$O$5)+1/--('[1]U$S'!$H$5:$H$1008=$L$5),ROWS($D$7:D35)),1))} -> 45629 | E35: {=IF(ROWS($E$7:E35)>COUNTIF('[1]U$S'!$H$5:$H$1008,$L$5),"",INDEX(CuentaUS,_xlfn.AGGREGATE(15,6,ROW('[1]U$S'!$H$5:$H$1008)-ROW('[1]U$S'!$O$5)+1/--('[1]U$S'!$H$5:$H$1008=$L$5),ROWS($E$7:E35)),6))} -> 11157.6 | F35: =IF(E35="","",IF(E35>0,SUMIFS('[1]UY$'!$L$5:$L$993,'[1]UY$'!$O$5:$O$993,"Cambio",'[1]UY$'!$E$5:$E$993,'Efecto TC'!D35),"")) -> 480000 | G35: =IF(F35="","",F35/E35) -> 43.020004 | H35: =IF(E35="","",F35/$F$2-F35/G35) -> 270.97143 | I35: =IF(H35="","",+H35+I34) -> -11658.629 | K35: 43 | L35: =+N33-N35 -> 258379.39 | N35: =+$L$24/K35 -> 10851934 | R35: =E35/$E$1001 -> 0.0013110504 | S35: =R35*G35 -> 0.056401392
A36: =MONTH(D36) -> 12 | B36: =YEAR(D36) -> 2024 | D36: {=IF(ROWS($D$7:D36)>COUNTIF('[1]U$S'!$H$5:$H$1008,$L$5),"",INDEX(CuentaUS,_xlfn.AGGREGATE(15,6,ROW('[1]U$S'!$H$5:$H$1008)-ROW('[1]U$S'!$O$5)+1/--('[1]U$S'!$H$5:$H$1008=$L$5),ROWS($D$7:D36)),1))} -> 45638 | E36: {=IF(ROWS($E$7:E36)>COUNTIF('[1]U$S'!$H$5:$H$1008,$L$5),"",INDEX(CuentaUS,_xlfn.AGGREGATE(15,6,ROW('[1]U$S'!$H$5:$H$1008)-ROW('[1]U$S'!$O$5)+1/--('[1]U$S'!$H$5:$H$1008=$L$5),ROWS($E$7:E36)),6))} -> 16949.15 | F36: =IF(E36="","",IF(E36>0,SUMIFS('[1]UY$'!$L$5:$L$993,'[1]UY$'!$O$5:$O$993,"Cambio",'[1]UY$'!$E$5:$E$993,'Efecto TC'!D36),"")) -> 750000 | G36: =IF(F36="","",F36/E36) -> 44.250007 | H36: =IF(E36="","",F36/$F$2-F36/G36) -> 907.99286 | I36: =IF(H36="","",+H36+I35) -> -10750.636 | K36: 44 | L36: =+N33-N36 -> 505014.26 | N36: =+$L$24/K36 -> 10605299 | R36: =E36/$E$1001 -> 0.0019915743 | S36: =R36*G36 -> 0.088127175
A37: =MONTH(D37) -> 12 | B37: =YEAR(D37) -> 2024 | D37: {=IF(ROWS($D$7:D37)>COUNTIF('[1]U$S'!$H$5:$H$1008,$L$5),"",INDEX(CuentaUS,_xlfn.AGGREGATE(15,6,ROW('[1]U$S'!$H$5:$H$1008)-ROW('[1]U$S'!$O$5)+1/--('[1]U$S'!$H$5:$H$1008=$L$5),ROWS($D$7:D37)),1))} -> 45644 | E37: {=IF(ROWS($E$7:E37)>COUNTIF('[1]U$S'!$H$5:$H$1008,$L$5),"",INDEX(CuentaUS,_xlfn.AGGREGATE(15,6,ROW('[1]U$S'!$H$5:$H$1008)-ROW('[1]U$S'!$O$5)+1/--('[1]U$S'!$H$5:$H$1008=$L$5),ROWS($E$7:E37)),6))} -> 14179.6 | F37: =IF(E37="","",IF(E37>0,SUMIFS('[1]UY$'!$L$5:$L$993,'[1]UY$'!$O$5:$O$993,"Cambio",'[1]UY$'!$E$5:$E$993,'Efecto TC'!D37),"")) -> 630000 | G37: =IF(F37="","",F37/E37) -> 44.430026 | H37: =IF(E37="","",F37/$F$2-F37/G37) -> 820.4 | I37: =IF(H37="","",+H37+I36) -> -9930.2362 | K37: 45 | L37: =+N33-N37 -> 740687.58 | N37: =+$L$24/K37 -> 10369626 | R37: =E37/$E$1001 -> 0.0016661441 | S37: =R37*G37 -> 0.074026827
A38: =MONTH(D38) -> 12 | B38: =YEAR(D38) -> 2024 | D38: {=IF(ROWS($D$7:D38)>COUNTIF('[1]U$S'!$H$5:$H$1008,$L$5),"",INDEX(CuentaUS,_xlfn.AGGREGATE(15,6,ROW('[1]U$S'!$H$5:$H$1008)-ROW('[1]U$S'!$O$5)+1/--('[1]U$S'!$H$5:$H$1008=$L$5),ROWS($D$7:D38)),1))} -> 45646 | E38: {=IF(ROWS($E$7:E38)>COUNTIF('[1]U$S'!$H$5:$H$1008,$L$5),"",INDEX(CuentaUS,_xlfn.AGGREGATE(15,6,ROW('[1]U$S'!$H$5:$H$1008)-ROW('[1]U$S'!$O$5)+1/--('[1]U$S'!$H$5:$H$1008=$L$5),ROWS($E$7:E38)),6))} -> 63091.48 | F38: =IF(E38="","",IF(E38>0,SUMIFS('[1]UY$'!$L$5:$L$993,'[1]UY$'!$O$5:$O$993,"Cambio",'[1]UY$'!$E$5:$E$993,'Efecto TC'!D38),"")) -> 2800000 | G38: =IF(F38="","",F38/E38) -> 44.380002 | H38: =IF(E38="","",F38/$F$2-F38/G38) -> 3575.1867 | I38: =IF(H38="","",+H38+I37) -> -6355.0495 | R38: =E38/$E$1001 -> 0.0074134319 | S38: =R38*G38 -> 0.32900812
A39: =MONTH(D39) -> 1 | B39: =YEAR(D39) -> 2025 | D39: {=IF(ROWS($D$7:D39)>COUNTIF('[1]U$S'!$H$5:$H$1008,$L$5),"",INDEX(CuentaUS,_xlfn.AGGREGATE(15,6,ROW('[1]U$S'!$H$5:$H$1008)-ROW('[1]U$S'!$O$5)+1/--('[1]U$S'!$H$5:$H$1008=$L$5),ROWS($D$7:D39)),1))} -> 45667 | E39: {=IF(ROWS($E$7:E39)>COUNTIF('[1]U$S'!$H$5:$H$1008,$L$5),"",INDEX(CuentaUS,_xlfn.AGGREGATE(15,6,ROW('[1]U$S'!$H$5:$H$1008)-ROW('[1]U$S'!$O$5)+1/--('[1]U$S'!$H$5:$H$1008=$L$5),ROWS($E$7:E39)),6))} -> 4566.21 | F39: =IF(E39="","",IF(E39>0,SUMIFS('[1]UY$'!$L$5:$L$993,'[1]UY$'!$O$5:$O$993,"Cambio",'[1]UY$'!$E$5:$E$993,'Efecto TC'!D39),"")) -> 200000 | G39: =IF(F39="","",F39/E39) -> 43.8 | H39: =IF(E39="","",F39/$F$2-F39/G39) -> 195.69476 | I39: =IF(H39="","",+H39+I38) -> -6159.3548 | R39: =E39/$E$1001 -> 0.00053654292 | S39: =R39*G39 -> 0.02350058
A40: =MONTH(D40) -> 1 | B40: =YEAR(D40) -> 2025 | D40: {=IF(ROWS($D$7:D40)>COUNTIF('[1]U$S'!$H$5:$H$1008,$L$5),"",INDEX(CuentaUS,_xlfn.AGGREGATE(15,6,ROW('[1]U$S'!$H$5:$H$1008)-ROW('[1]U$S'!$O$5)+1/--('[1]U$S'!$H$5:$H$1008=$L$5),ROWS($D$7:D40)),1))} -> 45671 | E40: {=IF(ROWS($E$7:E40)>COUNTIF('[1]U$S'!$H$5:$H$1008,$L$5),"",INDEX(CuentaUS,_xlfn.AGGREGATE(15,6,ROW('[1]U$S'!$H$5:$H$1008)-ROW('[1]U$S'!$O$5)+1/--('[1]U$S'!$H$5:$H$1008=$L$5),ROWS($E$7:E40)),6))} -> 1715.46 | F40: =IF(E40="","",IF(E40>0,SUMIFS('[1]UY$'!$L$5:$L$993,'[1]UY$'!$O$5:$O$993,"Cambio",'[1]UY$'!$E$5:$E$993,'Efecto TC'!D40),"")) -> 75000 | G40: =IF(F40="","",F40/E40) -> 43.720052 | H40: =IF(E40="","",F40/$F$2-F40/G40) -> 70.254286 | I40: =IF(H40="","",+H40+I39) -> -6089.1005 | R40: =E40/$E$1001 -> 0.00020157152 | S40: =R40*G40 -> 0.0088127175
...
